Workbook

Sheet Validaciones
A1: Nombre del Documento | J1: Clave: | K1: GRENVTPM003
J2: Revisión: | K2: 000
A3: Horarios envasado | J3: Fecha: | K3: 46108
J4: Página: | K4: NA
A6: ELABORÓ | E6: REVISÓ | J6: APROBÓ
A7: Supervisor de packaging | E7: Supervisor de packaging | J7: Gerente de packaging
D12: Codigo | E12: Horario | F12: HORAS TRABAJADAS | I12: Equipos
D13: 0 | E13: Descanso | F13: 0 | I13: Modulfill | J13: Llenadora
D14: 1 | E14: 07:30 - 16:30 | F14: 8 | I14: Variopac | J14: Lavadora
D15: 5 | E15: 15:30 - 00:30 | F15: 8 | I15: Varioline | J15: Etiquetadora
D16: 9 | E16: 23:30 - 08:30 | F16: 8 | I16: Pressant | J16: Variopac
D17: 4 | E17: 07:30 - 20:30 | F17: 12 | I17: Modulpal | J17: Pz
D18: 7 | E18: 19:30 - 08:30 | F18: 12 | I18: Brigadas | J18: Depa/Pale
E19: 03:30 - 16:30 | F19: 12 | I19: PM Day | J19: Enca/desenca
E20: 15:30 - 04:30 | F20: 12 | I20: Asepsia | J20: BT4
D21: 8 | E21: Vacaciones | F21: 8 | I21: Limpieza | J21: BT5
D22: 6 | E22: Cumpleaños | F22: 0 | I22: PRI
D23: 10 | E23: Descanso médico | F23: 0 | I23: PZ
D24: 11 | E24: Calamidad doméstica | F24: 8 | I24: APM
D25: 12 | E25: Evento | F25: 8 | I25: Capacitación
D26: 13 | E26: Cita médica | F26: 8
D27: 14 | E27: 07:30 - 20:30 F | F27: 12
D28: 15 | E28: 19:30 - 08:30 F | F28: 12
D29: 16 | E29: 03:30 - 16:30 F | F29: 12
D30: 17 | E30: 15:30 - 04:30 F | F30: 12
D31: 18 | E31: 12:30 - 00:30 | F31: 12
D32: 19 | E32: 23:30 - 12:30 | F32: 12
D33: 20 | E33: 11:30 - 00:30 F | F33: 12
D34: 21 | E34: 10:30 - 17:30 | F34: 12
D35: 22 | E35: Paternidad | F35: 8
D36: 23 | E36: 19:30 - 04:30 F | F36: 5
D37: 24 | E37: Desprogramación externa | F37: 8
... D39: 26 | E39: 12:30 - 20:00 | F39: 8
E40: NO COMPLETAR FIN VALIDACIONES

Sheet Horario linea de latas
B1: Nombre del Documento | E1: Clave: | F1: GRENVTPM003
E2: Revisión: | F2: 000
B3: Horarios envasado | E3: Fecha: | F3: 46108
E4: Página: | F4: NA
B6: ELABORÓ | C6: REVISÓ | E6: APROBÓ
B7: Supervisor de packaging | C7: Supervisor de packaging | E7: Gerente de packaging
B10: Cedula | C10: Grupo | D10: Nombre | G10: =+TEXT(H10,"dddd") -> martes | H10: 45860 | J10: =+TEXT(K10,"dddd") -> miércoles | K10: =+H10+1 -> 45861 | M10: =+TEXT(N10,"dddd") -> jueves | N10: =+K10+1 -> 45862 | P10: =+TEXT(Q10,"dddd") -> viernes | Q10: =+N10+1 -> 45863 | S10: =+TEXT(T10,"dddd") -> sábado | T10: =+Q10+1 -> 45864 | V10: =+TEXT(W10,"dddd") -> domingo | W10: =+T10+1 -> 45865 | Y10: =+TEXT(Z10,"dddd") -> lunes | Z10: =+W10+1 -> 45866 | AB10: =+TEXT(AC10,"dddd") -> martes | AC10: =+Z10+1 -> 45867 | AE10: =+TEXT(AF10,"dddd") -> miércoles | AF10: =+AC10+1 -> 45868 | AH10: =+TEXT(AI10,"dddd") -> jueves | AI10: =+AF10+1 -> 45869 | AK10: =+TEXT(AL10,"dddd") -> viernes | AL10: =+AI10+1 -> 45870 | AN10: =+TEXT(AO10,"dddd") -> sábado | AO10: =+AL10+1 -> 45871 | AQ10: =+TEXT(AR10,"dddd") -> domingo | AR10: =+AO10+1 -> 45872 | AT10: =+TEXT(AU10,"dddd") -> lunes | AU10: =+AR10+1 -> 45873 | AW10: =+TEXT(AX10,"dddd") -> martes | AX10: =+AU10+1 -> 45874 | AZ10: =+TEXT(BA10,"dddd") -> miércoles | BA10: =+AX10+1 -> 45875 | BC10: =+TEXT(BD10,"dddd") -> jueves | BD10: =+BA10+1 -> 45876 | BF10: =+TEXT(BG10,"dddd") -> viernes | BG10: =+BD10+1 -> 45877 | BI10: =+TEXT(BJ10,"dddd") -> sábado | BJ10: =+BG10+1 -> 45878 | BL10: =+TEXT(BM10,"dddd") -> domingo | BM10: =+BJ10+1 -> 45879 | BO10: =+TEXT(BP10,"dddd") -> lunes | BP10: =+BM10+1 -> 45880 | BR10: =+TEXT(BS10,"dddd") -> martes | BS10: =+BP10+1 -> 45881 | BU10: =+TEXT(BV10,"dddd") -> miércoles | BV10: =+BS10+1 -> 45882 | BX10: =+TEXT(BY10,"dddd") -> jueves | BY10: =+BV10+1 -> 45883 | CA10: =+TEXT(CB10,"dddd") -> viernes | CB10: =+BY10+1 -> 45884 | CD10: =+TEXT(CE10,"dddd") -> sábado | CE10: =+CB10+1 -> 45885 | CG10: =+TEXT(CH10,"dddd") -> domingo | CH10: =+CE10+1 -> 45886 | CJ10: =+TEXT(CK10,"dddd") -> lunes | CK10: =+CH10+1 -> 45887 | CM10: =+TEXT(CN10,"dddd") -> martes | CN10: =+CK10+1 -> 45888 | CP10: =+TEXT(CQ10,"dddd") -> miércoles | CQ10: =+CN10+1 -> 45889 | CS10: =+TEXT(CT10,"dddd") -> jueves | CT10: =+CQ10+1 -> 45890 | CV10: =+TEXT(CW10,"dddd") -> viernes | CW10: =+CT10+1 -> 45891 | CY10: =+TEXT(CZ10,"dddd") -> sábado | CZ10: =+CW10+1 -> 45892 | DB10: =+TEXT(DC10,"dddd") -> domingo | DC10: =+CZ10+1 -> 45893 | DE10: =+TEXT(DF10,"dddd") -> lunes | DF10: =+DC10+1 -> 45894 | DH10: =+TEXT(DI10,"dddd") -> martes | DI10: =+DF10+1 -> 45895 | DK10: =+TEXT(DL10,"dddd") -> miércoles | DL10: =+DI10+1 -> 45896 | DN10: =+TEXT(DO10,"dddd") -> jueves | DO10: =+DL10+1 -> 45897 | DQ10: =+TEXT(DR10,"dddd") -> viernes | DR10: =+DO10+1 -> 45898 | DT10: =+TEXT(DU10,"dddd") -> sábado | DU10: =+DR10+1 -> 45899 | DW10: =+TEXT(DX10,"dddd") -> domingo | DX10: =+DU10+1 -> 45900 | DZ10: =+TEXT(EA10,"dddd") -> lunes | EA10: =+DX10+1 -> 45901 | EC10: =+TEXT(ED10,"dddd") -> martes | ED10: =+EA10+1 -> 45902 | EF10: =+TEXT(EG10,"dddd") -> miércoles | EG10: =+ED10+1 -> 45903 | EI10: =+TEXT(EJ10,"dddd") -> jueves | EJ10: =+EG10+1 -> 45904 | EL10: =+TEXT(EM10,"dddd") -> viernes | EM10: =+EJ10+1 -> 45905 | EO10: =+TEXT(EP10,"dddd") -> sábado | EP10: =+EM10+1 -> 45906 | ER10: =+TEXT(ES10,"dddd") -> domingo | ES10: =+EP10+1 -> 45907 | EU10: =+TEXT(EV10,"dddd") -> lunes | EV10: =+ES10+1 -> 45908 | EX10: =+TEXT(EY10,"dddd") -> martes | EY10: =+EV10+1 -> 45909 | FA10: =+TEXT(FB10,"dddd") -> miércoles | FB10: =+EY10+1 -> 45910 | FD10: =+TEXT(FE10,"dddd") -> jueves | FE10: =+FB10+1 -> 45911 | FG10: =+TEXT(FH10,"dddd") -> viernes | FH10: =+FE10+1 -> 45912 | FJ10: =+TEXT(FK10,"dddd") -> sábado | FK10: =+FH10+1 -> 45913 | FM10: =+TEXT(FN10,"dddd") -> domingo | FN10: =+FK10+1 -> 45914 | FP10: =+TEXT(FQ10,"dddd") -> lunes | FQ10: =+FN10+1 -> 45915 | FS10: =+TEXT(FT10,"dddd") -> martes | FT10: =+FQ10+1 -> 45916 | FV10: =+TEXT(FW10,"dddd") -> miércoles | FW10: =+FT10+1 -> 45917 | FY10: =+TEXT(FZ10,"dddd") -> jueves | FZ10: =+FW10+1 -> 45918 | GB10: =+TEXT(GC10,"dddd") -> viernes | GC10: =+FZ10+1 -> 45919 | GE10: =+TEXT(GF10,"dddd") -> sábado | GF10: =+GC10+1 -> 45920 | GH10: =+TEXT(GI10,"dddd") -> domingo | GI10: =+GF10+1 -> 45921 | GK10: =+TEXT(GL10,"dddd") -> lunes | GL10: =+GI10+1 -> 45922 | GN10: =+TEXT(GO10,"dddd") -> martes | GO10: =+GL10+1 -> 45923 | GQ10: =+TEXT(GR10,"dddd") -> miércoles | GR10: =+GO10+1 -> 45924 | GT10: =+TEXT(GU10,"dddd") -> jueves | GU10: =+GR10+1 -> 45925 | GW10: =+TEXT(GX10,"dddd") -> viernes | GX10: =+GU10+1 -> 45926 | GZ10: =+TEXT(HA10,"dddd") -> sábado | HA10: =+GX10+1 -> 45927 | HC10: =+TEXT(HD10,"dddd") -> domingo | HD10: =+HA10+1 -> 45928 | HF10: =+TEXT(HG10,"dddd") -> lunes | HG10: =+HD10+1 -> 45929 | HI10: =+TEXT(HJ10,"dddd") -> martes | HJ10: =+HG10+1 -> 45930 | HL10: =+TEXT(HM10,"dddd") -> miércoles | HM10: =+HJ10+1 -> 45931 | HO10: =+TEXT(HP10,"dddd") -> jueves | HP10: =+HM10+1 -> 45932 | HR10: =+TEXT(HS10,"dddd") -> viernes | HS10: =+HP10+1 -> 45933 | HU10: =+TEXT(HV10,"dddd") -> sábado | HV10: =+HS10+1 -> 45934 | HX10: =+TEXT(HY10,"dddd") -> domingo | HY10: =+HV10+1 -> 45935 | IA10: =+TEXT(IB10,"dddd") -> lunes | IB10: =+HY10+1 -> 45936 | ID10: =+TEXT(IE10,"dddd") -> martes | IE10: =+IB10+1 -> 45937 | IG10: =+TEXT(IH10,"dddd") -> miércoles | IH10: =+IE10+1 -> 45938 | IJ10: =+TEXT(IK10,"dddd") -> jueves | IK10: =+IH10+1 -> 45939 | IM10: =+TEXT(IN10,"dddd") -> viernes | IN10: =+IK10+1 -> 45940 | IP10: =+TEXT(IQ10,"dddd") -> sábado | IQ10: =+IN10+1 -> 45941 | IS10: =+TEXT(IT10,"dddd") -> domingo | IT10: =+IQ10+1 -> 45942 | IV10: =+TEXT(IW10,"dddd") -> lunes | IW10: =+IT10+1 -> 45943 | IY10: =+TEXT(IZ10,"dddd") -> martes | IZ10: =+IW10+1 -> 45944 | JB10: =+TEXT(JC10,"dddd") -> miércoles | JC10: =+IZ10+1 -> 45945 | JE10: =+TEXT(JF10,"dddd") -> jueves | JF10: =+JC10+1 -> 45946 | JH10: =+TEXT(JI10,"dddd") -> viernes | JI10: =+JF10+1 -> 45947 | JK10: =+TEXT(JL10,"dddd") -> sábado | JL10: =+JI10+1 -> 45948 | JN10: =+TEXT(JO10,"dddd") -> domingo | JO10: =+JL10+1 -> 45949 | JQ10: =+TEXT(JR10,"dddd") -> lunes | JR10: =+JO10+1 -> 45950 | JT10: =+TEXT(JU10,"dddd") -> martes | JU10: =+JR10+1 -> 45951 | JW10: =+TEXT(JX10,"dddd") -> miércoles | JX10: =+JU10+1 -> 45952 | JZ10: =+TEXT(KA10,"dddd") -> jueves | KA10: =+JX10+1 -> 45953 | KC10: =+TEXT(KD10,"dddd") -> viernes | KD10: =+KA10+1 -> 45954 | KF10: =+TEXT(KG10,"dddd") -> sábado | KG10: =+KD10+1 -> 45955 | KI10: =+TEXT(KJ10,"dddd") -> domingo | KJ10: =+KG10+1 -> 45956 | KL10: =+TEXT(KM10,"dddd") -> lunes | KM10: =+KJ10+1 -> 45957 | KO10: =+TEXT(KP10,"dddd") -> martes | KP10: =+KM10+1 -> 45958 | KR10: =+TEXT(KS10,"dddd") -> miércoles | KS10: =+KP10+1 -> 45959 | KU10: =+TEXT(KV10,"dddd") -> jueves | KV10: =+KS10+1 -> 45960 | KX10: =+TEXT(KY10,"dddd") -> viernes | KY10: =+KV10+1 -> 45961 | LA10: =+TEXT(LB10,"dddd") -> sábado | LB10: =+KY10+1 -> 45962 | LD10: =+TEXT(LE10,"dddd") -> domingo | LE10: =+LB10+1 -> 45963 | LG10: =+TEXT(LH10,"dddd") -> lunes | LH10: =+LE10+1 -> 45964 | LJ10: =+TEXT(LK10,"dddd") -> martes | LK10: =+LH10+1 -> 45965 | LM10: =+TEXT(LN10,"dddd") -> miércoles | LN10: =+LK10+1 -> 45966 | LP10: =+TEXT(LQ10,"dddd") -> jueves | LQ10: =+LN10+1 -> 45967 | LS10: =+TEXT(LT10,"dddd") -> viernes | LT10: =+LQ10+1 -> 45968 | LV10: =+TEXT(LW10,"dddd") -> sábado | LW10: =+LT10+1 -> 45969 | LY10: =+TEXT(LZ10,"dddd") -> domingo | LZ10: =+LW10+1 -> 45970 | MB10: =+TEXT(MC10,"dddd") -> lunes | MC10: =+LZ10+1 -> 45971 | ME10: =+TEXT(MF10,"dddd") -> martes | MF10: =+MC10+1 -> 45972 | MH10: =+TEXT(MI10,"dddd") -> miércoles | MI10: =+MF10+1 -> 45973 | MK10: =+TEXT(ML10,"dddd") -> jueves | ML10: =+MI10+1 -> 45974 | MN10: =+TEXT(MO10,"dddd") -> viernes | MO10: =+ML10+1 -> 45975 | MQ10: =+TEXT(MR10,"dddd") -> sábado | MR10: =+MO10+1 -> 45976 | MT10: =+TEXT(MU10,"dddd") -> domingo | MU10: =+MR10+1 -> 45977 | MW10: =+TEXT(MX10,"dddd") -> lunes | MX10: =+MU10+1 -> 45978 | MZ10: =+TEXT(NA10,"dddd") -> martes | NA10: =+MX10+1 -> 45979 | NC10: =+TEXT(ND10,"dddd") -> miércoles | ND10: =+NA10+1 -> 45980 | NF10: =+TEXT(NG10,"dddd") -> jueves | NG10: =+ND10+1 -> 45981 | NI10: =+TEXT(NJ10,"dddd") -> viernes | NJ10: =+NG10+1 -> 45982 | NL10: =+TEXT(NM10,"dddd") -> sábado | NM10: =+NJ10+1 -> 45983 | NO10: =+TEXT(NP10,"dddd") -> domingo | NP10: =+NM10+1 -> 45984 | NR10: =+TEXT(NS10,"dddd") -> lunes | NS10: =+NP10+1 -> 45985 | NU10: =+TEXT(NV10,"dddd") -> martes | NV10: =+NS10+1 -> 45986 | NX10: =+TEXT(NY10,"dddd") -> miércoles | NY10: =+NV10+1 -> 45987 | OA10: =+TEXT(OB10,"dddd") -> jueves | OB10: =+NY10+1 -> 45988 | OD10: =+TEXT(OE10,"dddd") -> viernes | OE10: =+OB10+1 -> 45989 | OG10: =+TEXT(OH10,"dddd") -> sábado | OH10: =+OE10+1 -> 45990 | OJ10: =+TEXT(OK10,"dddd") -> domingo | OK10: =+OH10+1 -> 45991 | OM10: =+TEXT(ON10,"dddd") -> lunes | ON10: =+OK10+1 -> 45992 | OP10: =+TEXT(OQ10,"dddd") -> martes | OQ10: =+ON10+1 -> 45993 | OS10: =+TEXT(OT10,"dddd") -> miércoles | OT10: =+OQ10+1 -> 45994 | OV10: =+TEXT(OW10,"dddd") -> jueves | OW10: =+OT10+1 -> 45995 | OY10: =+TEXT(OZ10,"dddd") -> viernes | OZ10: =+OW10+1 -> 45996 | PB10: =+TEXT(PC10,"dddd") -> sábado | PC10: =+OZ10+1 -> 45997 | PE10: =+TEXT(PF10,"dddd") -> domingo | PF10: =+PC10+1 -> 45998 | PH10: =+TEXT(PI10,"dddd") -> lunes | PI10: =+PF10+1 -> 45999 | PK10: =+TEXT(PL10,"dddd") -> martes | PL10: =+PI10+1 -> 46000 | PN10: =+TEXT(PO10,"dddd") -> miércoles | PO10: =+PL10+1 -> 46001 | PQ10: =+TEXT(PR10,"dddd") -> jueves | PR10: =+PO10+1 -> 46002 | PT10: =+TEXT(PU10,"dddd") -> viernes | PU10: =+PR10+1 -> 46003 | PW10: =+TEXT(PX10,"dddd") -> sábado | PX10: =+PU10+1 -> 46004 | PZ10: =+TEXT(QA10,"dddd") -> domingo | QA10: =+PX10+1 -> 46005 | QC10: =+TEXT(QD10,"dddd") -> lunes | QD10: =+QA10+1 -> 46006 | QF10: =+TEXT(QG10,"dddd") -> martes | QG10: =+QD10+1 -> 46007 | QI10: =+TEXT(QJ10,"dddd") -> miércoles | QJ10: =+QG10+1 -> 46008 | QM10: =+QJ10+1 -> 46009 | QO10: =+TEXT(QP10,"dddd") -> viernes | QP10: =+QM10+1 -> 46010 | QR10: =+TEXT(QS10,"dddd") -> sábado | QS10: =+QP10+1 -> 46011 | QU10: =+TEXT(QV10,"dddd") -> domingo | QV10: =+QS10+1 -> 46012 | QX10: =+TEXT(QY10,"dddd") -> lunes | QY10: =+QV10+1 -> 46013 | RA10: =+TEXT(RB10,"dddd") -> martes | RB10: =+QY10+1 -> 46014 | RD10: =+TEXT(RE10,"dddd") -> miércoles | RE10: =+RB10+1 -> 46015 | RG10: =+TEXT(RH10,"dddd") -> jueves | RH10: =+RE10+1 -> 46016 | RJ10: =+TEXT(RK10,"dddd") -> viernes | RK10: =+RH10+1 -> 46017 | RM10: =+TEXT(RN10,"dddd") -> sábado | RN10: =+RK10+1 -> 46018 | RP10: =+TEXT(RQ10,"dddd") -> domingo | RQ10: =+RN10+1 -> 46019 | RS10: =+TEXT(RT10,"dddd") -> lunes | RT10: =+RQ10+1 -> 46020 | RV10: =+TEXT(RW10,"dddd") -> martes | RW10: =+RT10+1 -> 46021 | RY10: =+TEXT(RZ10,"dddd") -> miércoles | RZ10: =+RW10+1 -> 46022 | SB10: =+TEXT(SC10,"dddd") -> jueves | SC10: =+RZ10+1 -> 46023 | SE10: =+TEXT(SF10,"dddd") -> viernes | SF10: =+SC10+1 -> 46024 | SH10: =+TEXT(SI10,"dddd") -> sábado | SI10: =+SF10+1 -> 46025 | SK10: =+TEXT(SL10,"dddd") -> domingo | SL10: =+SI10+1 -> 46026 | SN10: =+TEXT(SO10,"dddd") -> lunes | SO10: =+SL10+1 -> 46027 | SQ10: =+TEXT(SR10,"dddd") -> martes | SR10: =+SO10+1 -> 46028 | ST10: =+TEXT(SU10,"dddd") -> miércoles | SU10: =+SR10+1 -> 46029 | SW10: =+TEXT(SX10,"dddd") -> jueves | SX10: =+SU10+1 -> 46030 | SZ10: =+TEXT(TA10,"dddd") -> viernes | TA10: =+SX10+1 -> 46031 | TC10: =+TEXT(TD10,"dddd") -> sábado | TD10: =+TA10+1 -> 46032 | TF10: =+TEXT(TG10,"dddd") -> domingo | TG10: =+TD10+1 -> 46033 | TI10: =+TEXT(TJ10,"dddd") -> lunes | TJ10: =+TG10+1 -> 46034 | TL10: =+TEXT(TM10,"dddd") -> martes | TM10: =+TJ10+1 -> 46035 | TO10: =+TEXT(TP10,"dddd") -> miércoles | TP10: =+TM10+1 -> 46036 | TR10: =+TEXT(TS10,"dddd") -> jueves | TS10: =+TP10+1 -> 46037 | TU10: =+TEXT(TV10,"dddd") -> viernes | TV10: =+TS10+1 -> 46038 | TX10: =+TEXT(TY10,"dddd") -> sábado | TY10: =+TV10+1 -> 46039 | UA10: =+TEXT(UB10,"dddd") -> domingo | UB10: =+TY10+1 -> 46040 | UD10: =+TEXT(UE10,"dddd") -> lunes | UE10: =+UB10+1 -> 46041 | UG10: =+TEXT(UH10,"dddd") -> martes | UH10: =+UE10+1 -> 46042 | UJ10: =+TEXT(UK10,"dddd") -> miércoles | UK10: =+UH10+1 -> 46043 | UM10: =+TEXT(UN10,"dddd") -> jueves | UN10: =+UK10+1 -> 46044 | UP10: =+TEXT(UQ10,"dddd") -> viernes | UQ10: =+UN10+1 -> 46045 | US10: =+TEXT(UT10,"dddd") -> sábado | UT10: =+UQ10+1 -> 46046 | UV10: =+TEXT(UW10,"dddd") -> domingo | UW10: =+UT10+1 -> 46047 | UY10: =+TEXT(UZ10,"dddd") -> lunes | UZ10: =+UW10+1 -> 46048 | VB10: =+TEXT(VC10,"dddd") -> martes | VC10: =+UZ10+1 -> 46049 | VE10: =+TEXT(VF10,"dddd") -> miércoles | VF10: =+VC10+1 -> 46050 | VH10: =+TEXT(VI10,"dddd") -> jueves | VI10: =+VF10+1 -> 46051 | VK10: =+TEXT(VL10,"dddd") -> viernes | VL10: =+VI10+1 -> 46052 | VN10: =+TEXT(VO10,"dddd") -> sábado | VO10: =+VL10+1 -> 46053 | VQ10: =+TEXT(VR10,"dddd") -> domingo | VR10: =+VO10+1 -> 46054 | VT10: =+TEXT(VU10,"dddd") -> lunes | VU10: =+VR10+1 -> 46055 | VW10: =+TEXT(VX10,"dddd") -> martes | VX10: =+VU10+1 -> 46056 | VZ10: =+TEXT(WA10,"dddd") -> miércoles | WA10: =+VX10+1 -> 46057 | WC10: =+TEXT(WD10,"dddd") -> jueves | WD10: =+WA10+1 -> 46058 | WF10: =+TEXT(WG10,"dddd") -> viernes | WG10: =+WD10+1 -> 46059 | WI10: =+TEXT(WJ10,"dddd") -> sábado | WJ10: =+WG10+1 -> 46060 | WL10: =+TEXT(WM10,"dddd") -> domingo | WM10: =+WJ10+1 -> 46061 | WO10: =+TEXT(WP10,"dddd") -> lunes | WP10: =+WM10+1 -> 46062 | WR10: =+TEXT(WS10,"dddd") -> martes | WS10: =+WP10+1 -> 46063 | WU10: =+TEXT(WV10,"dddd") -> miércoles | WV10: =+WS10+1 -> 46064 | WX10: =+TEXT(WY10,"dddd") -> jueves | WY10: =+WV10+1 -> 46065 | XA10: =+TEXT(XB10,"dddd") -> viernes | XB10: =+WY10+1 -> 46066 | XD10: =+TEXT(XE10,"dddd") -> sábado | XE10: =+XB10+1 -> 46067 | XG10: =+TEXT(XH10,"dddd") -> domingo | XH10: =+XE10+1 -> 46068 | XJ10: =+TEXT(XK10,"dddd") -> lunes | XK10: =+XH10+1 -> 46069 | XM10: =+TEXT(XN10,"dddd") -> martes | XN10: =+XK10+1 -> 46070 | XP10: =+TEXT(XQ10,"dddd") -> miércoles | XQ10: =+XN10+1 -> 46071 | XS10: =+TEXT(XT10,"dddd") -> jueves | XT10: =+XQ10+1 -> 46072 | XV10: =+TEXT(XW10,"dddd") -> viernes | XW10: =+XT10+1 -> 46073 | XY10: =+TEXT(XZ10,"dddd") -> sábado | XZ10: =+XW10+1 -> 46074 | YB10: =+TEXT(YC10,"dddd") -> domingo | YC10: =+XZ10+1 -> 46075 | YE10: =+TEXT(YF10,"dddd") -> lunes | YF10: =+YC10+1 -> 46076 | YH10: =+TEXT(YI10,"dddd") -> martes | YI10: =+YF10+1 -> 46077 | YK10: =+TEXT(YL10,"dddd") -> miércoles | YL10: =+YI10+1 -> 46078 | YN10: =+TEXT(YO10,"dddd") -> jueves | YO10: =+YL10+1 -> 46079 | YQ10: =+TEXT(YR10,"dddd") -> viernes | YR10: =+YO10+1 -> 46080 | YT10: =+TEXT(YU10,"dddd") -> sábado | YU10: =+YR10+1 -> 46081 | YW10: =+TEXT(YX10,"dddd") -> domingo | YX10: =+YU10+1 -> 46082 | YZ10: =+TEXT(ZA10,"dddd") -> lunes | ZA10: =+YX10+1 -> 46083 | ZC10: =+TEXT(ZD10,"dddd") -> martes | ZD10: =+ZA10+1 -> 46084 | ZF10: =+TEXT(ZG10,"dddd") -> miércoles | ZG10: =+ZD10+1 -> 46085 | ZI10: =+TEXT(ZJ10,"dddd") -> jueves | ZJ10: =+ZG10+1 -> 46086 | ZL10: =+TEXT(ZM10,"dddd") -> viernes | ZM10: =+ZJ10+1 -> 46087 | ZO10: =+TEXT(ZP10,"dddd") -> sábado | ZP10: =+ZM10+1 -> 46088 | ZR10: =+TEXT(ZS10,"dddd") -> domingo | ZS10: =+ZP10+1 -> 46089 | ZU10: =+TEXT(ZV10,"dddd") -> lunes | ZV10: =+ZS10+1 -> 46090 | ZX10: =+TEXT(ZY10,"dddd") -> martes | ZY10: =+ZV10+1 -> 46091 | AAA10: =+TEXT(AAB10,"dddd") -> miércoles | AAB10: =+ZY10+1 -> 46092 | AAD10: =+TEXT(AAE10,"dddd") -> jueves | AAE10: =+AAB10+1 -> 46093 | AAG10: =+TEXT(AAH10,"dddd") -> viernes | AAH10: =+AAE10+1 -> 46094 | AAJ10: =+TEXT(AAK10,"dddd") -> sábado | AAK10: =+AAH10+1 -> 46095 | AAM10: =+TEXT(AAN10,"dddd") -> domingo | AAN10: =+AAK10+1 -> 46096 | AAP10: =+TEXT(AAQ10,"dddd") -> lunes | AAQ10: =+AAN10+1 -> 46097 | AAS10: =+TEXT(AAT10,"dddd") -> martes | AAT10: =+AAQ10+1 -> 46098 | AAV10: =+TEXT(AAW10,"dddd") -> miércoles | AAW10: =+AAT10+1 -> 46099 | AAY10: =+TEXT(AAZ10,"dddd") -> jueves | AAZ10: =+AAW10+1 -> 46100 | ABB10: =+TEXT(ABC10,"dddd") -> viernes | ABC10: =+AAZ10+1 -> 46101 | ABE10: =+TEXT(ABF10,"dddd") -> sábado | ABF10: =+ABC10+1 -> 46102 | ABH10: =+TEXT(ABI10,"dddd") -> domingo | ABI10: =+ABF10+1 -> 46103 | ABK10: =+TEXT(ABL10,"dddd") -> lunes | ABL10: =+ABI10+1 -> 46104 | ABN10: =+TEXT(ABO10,"dddd") -> martes | ABO10: =+ABL10+1 -> 46105 | ABQ10: =+TEXT(ABR10,"dddd") -> miércoles | ABR10: =+ABO10+1 -> 46106 | ABT10: =+TEXT(ABU10,"dddd") -> jueves | ABU10: =+ABR10+1 -> 46107 | ABW10: =+TEXT(ABX10,"dddd") -> viernes | ABX10: =+ABU10+1 -> 46108 | ABZ10: =+TEXT(ACA10,"dddd") -> sábado | ACA10: =+ABX10+1 -> 46109 | ACC10: =+TEXT(ACD10,"dddd") -> domingo | ACD10: =+ACA10+1 -> 46110 | ACF10: LUNES | ACG10: =+ACD10+1 -> 46111 | ACI10: MARTES | ACJ10: =+ACG10+1 -> 46112 | ACL10: MIERCOLES | ACM10: =+ACJ10+1 -> 46113 | ACO10: JUEVES | ACP10: =+ACM10+1 -> 46114 | ACR10: VIERNES | ACS10: =+ACP10+1 -> 46115 | ACU10: SABADO | ACV10: =+ACS10+1 -> 46116 | ACX10: DOMINGO | ACY10: =+ACV10+1 -> 46117 | ADA10: =+TEXT(ADB10,"dddd") -> lunes | ADB10: =+ACY10+1 -> 46118 | ADD10: =+TEXT(ADE10,"dddd") -> martes | ADE10: =+ADB10+1 -> 46119 | ADG10: =+TEXT(ADH10,"dddd") -> miércoles | ADH10: =+ADE10+1 -> 46120 | ADJ10: =+TEXT(ADK10,"dddd") -> jueves | ADK10: =+ADH10+1 -> 46121 | ADM10: =+TEXT(ADN10,"dddd") -> viernes | ADN10: =+ADK10+1 -> 46122 | ADP10: =+TEXT(ADQ10,"dddd") -> sábado | ADQ10: =+ADN10+1 -> 46123 | ADS10: =+TEXT(ADT10,"dddd") -> domingo | ADT10: =+ADQ10+1 -> 46124 | ADV10: =+TEXT(ADW10,"dddd") -> lunes | ADW10: =+ADT10+1 -> 46125 | ADY10: =+TEXT(ADZ10,"dddd") -> martes | ADZ10: =+ADW10+1 -> 46126 | AEB10: =+TEXT(AEC10,"dddd") -> miércoles | AEC10: =+ADZ10+1 -> 46127 | AEE10: =+TEXT(AEF10,"dddd") -> jueves | AEF10: =+AEC10+1 -> 46128 | AEH10: =+TEXT(AEI10,"dddd") -> viernes | AEI10: =+AEF10+1 -> 46129 | AEK10: =+TEXT(AEL10,"dddd") -> sábado | AEL10: =+AEI10+1 -> 46130 | AEN10: =+TEXT(AEO10,"dddd") -> domingo | AEO10: =+AEL10+1 -> 46131 | AEQ10: =+TEXT(AER10,"dddd") -> lunes | AER10: =+AEO10+1 -> 46132 | AET10: =+TEXT(AEU10,"dddd") -> martes | AEU10: =+AER10+1 -> 46133 | AEW10: =+TEXT(AEX10,"dddd") -> miércoles | AEX10: =+AEU10+1 -> 46134 | AEZ10: =+TEXT(AFA10,"dddd") -> jueves | AFA10: =+AEX10+1 -> 46135 | AFC10: =+TEXT(AFD10,"dddd") -> viernes | AFD10: =+AFA10+1 -> 46136 | AFF10: =+TEXT(AFG10,"dddd") -> sábado | AFG10: =+AFD10+1 -> 46137 | AFI10: =+TEXT(AFJ10,"dddd") -> domingo | AFJ10: =+AFG10+1 -> 46138 | AFL10: =+TEXT(AFM10,"dddd") -> lunes | AFM10: =+AFJ10+1 -> 46139 | AFO10: =+TEXT(AFP10,"dddd") -> martes | AFP10: =+AFM10+1 -> 46140 | AFR10: =+TEXT(AFS10,"dddd") -> miércoles | AFS10: =+AFP10+1 -> 46141 | AFU10: =+TEXT(AFV10,"dddd") -> jueves | AFV10: =+AFS10+1 -> 46142 | AFX10: =+TEXT(AFY10,"dddd") -> viernes | AFY10: =+AFV10+1 -> 46143 | AGA10: =+TEXT(AGB10,"dddd") -> sábado | AGB10: =+AFY10+1 -> 46144 | AGD10: =+TEXT(AGE10,"dddd") -> domingo | AGE10: =+AGB10+1 -> 46145 | AGG10: =+TEXT(AGH10,"dddd") -> lunes | AGH10: =+AGE10+1 -> 46146 | AGJ10: =+TEXT(AGK10,"dddd") -> martes | AGK10: =+AGH10+1 -> 46147 | AGM10: =+TEXT(AGN10,"dddd") -> miércoles | AGN10: =+AGK10+1 -> 46148 | AGP10: =+TEXT(AGQ10,"dddd") -> jueves | AGQ10: =+AGN10+1 -> 46149 | AGS10: =+TEXT(AGT10,"dddd") -> viernes | AGT10: =+AGQ10+1 -> 46150 | AGV10: =+TEXT(AGW10,"dddd") -> sábado | AGW10: =+AGT10+1 -> 46151 | AGY10: =+TEXT(AGZ10,"dddd") -> domingo | AGZ10: =+AGW10+1 -> 46152 | AHB10: =+TEXT(AHC10,"dddd") -> lunes | AHC10: =+AGZ10+1 -> 46153 | AHE10: =+TEXT(AHF10,"dddd") -> martes | AHF10: =+AHC10+1 -> 46154 | AHH10: =+TEXT(AHI10,"dddd") -> miércoles | AHI10: =+AHF10+1 -> 46155 | AHK10: =+TEXT(AHL10,"dddd") -> jueves | AHL10: =+AHI10+1 -> 46156 | AHN10: =+TEXT(AHO10,"dddd") -> viernes | AHO10: =+AHL10+1 -> 46157 | AHQ10: =+TEXT(AHR10,"dddd") -> sábado | AHR10: =+AHO10+1 -> 46158 | AHT10: =+TEXT(AHU10,"dddd") -> domingo | AHU10: =+AHR10+1 -> 46159 | AHW10: =+TEXT(AHX10,"dddd") -> lunes | AHX10: =+AHU10+1 -> 46160 | AHZ10: =+TEXT(AIA10,"dddd") -> martes | AIA10: =+AHX10+1 -> 46161 | AIC10: =+TEXT(AID10,"dddd") -> miércoles | AID10: =+AIA10+1 -> 46162 | AIF10: =+TEXT(AIG10,"dddd") -> jueves | AIG10: =+AID10+1 -> 46163 | AII10: =+TEXT(AIJ10,"dddd") -> viernes | AIJ10: =+AIG10+1 -> 46164 | AIL10: =+TEXT(AIM10,"dddd") -> sábado | AIM10: =+AIJ10+1 -> 46165 | AIO10: =+TEXT(AIP10,"dddd") -> domingo | AIP10: =+AIM10+1 -> 46166 | AIR10: =+TEXT(AIS10,"dddd") -> lunes | AIS10: =+AIP10+1 -> 46167 | AIU10: =+TEXT(AIV10,"dddd") -> martes | AIV10: =+AIS10+1 -> 46168 | AIX10: =+TEXT(AIY10,"dddd") -> miércoles | AIY10: =+AIV10+1 -> 46169 | AJA10: =+TEXT(AJB10,"dddd") -> jueves | AJB10: =+AIY10+1 -> 46170 | AJD10: =+TEXT(AJE10,"dddd") -> viernes | AJE10: =+AJB10+1 -> 46171 | AJG10: =+TEXT(AJH10,"dddd") -> sábado | AJH10: =+AJE10+1 -> 46172 | AJJ10: =+TEXT(AJK10,"dddd") -> domingo | AJK10: =+AJH10+1 -> 46173 | AJM10: =+TEXT(AJN10,"dddd") -> lunes | AJN10: =+AJK10+1 -> 46174 | AJP10: =+TEXT(AJQ10,"dddd") -> martes | AJQ10: =+AJN10+1 -> 46175 | AJS10: =+TEXT(AJT10,"dddd") -> miércoles | AJT10: =+AJQ10+1 -> 46176 | AJV10: =+TEXT(AJW10,"dddd") -> jueves | AJW10: =+AJT10+1 -> 46177 | AJY10: =+TEXT(AJZ10,"dddd") -> viernes | AJZ10: =+AJW10+1 -> 46178 | AKB10: =+TEXT(AKC10,"dddd") -> sábado | AKC10: =+AJZ10+1 -> 46179 | AKE10: =+TEXT(AKF10,"dddd") -> domingo | AKF10: =+AKC10+1 -> 46180 | AKH10: =+TEXT(AKI10,"dddd") -> lunes | AKI10: =+AKF10+1 -> 46181 | AKK10: =+TEXT(AKL10,"dddd") -> martes | AKL10: =+AKI10+1 -> 46182 | AKN10: =+TEXT(AKO10,"dddd") -> miércoles | AKO10: =+AKL10+1 -> 46183 | AKQ10: =+TEXT(AKR10,"dddd") -> jueves | AKR10: =+AKO10+1 -> 46184 | AKT10: =+TEXT(AKU10,"dddd") -> viernes | AKU10: =+AKR10+1 -> 46185 | AKW10: =+TEXT(AKX10,"dddd") -> sábado | AKX10: =+AKU10+1 -> 46186 | AKZ10: =+TEXT(ALA10,"dddd") -> domingo | ALA10: =+AKX10+1 -> 46187 | ALC10: =+TEXT(ALD10,"dddd") -> lunes | ALD10: =+ALA10+1 -> 46188 | ALF10: =+TEXT(ALG10,"dddd") -> martes | ALG10: =+ALD10+1 -> 46189 | ALI10: =+TEXT(ALJ10,"dddd") -> miércoles | ALJ10: =+ALG10+1 -> 46190 | ALL10: =+TEXT(ALM10,"dddd") -> jueves | ALM10: =+ALJ10+1 -> 46191 | ALO10: =+TEXT(ALP10,"dddd") -> viernes | ALP10: =+ALM10+1 -> 46192 | ALR10: =+TEXT(ALS10,"dddd") -> sábado | ALS10: =+ALP10+1 -> 46193 | ALU10: =+TEXT(ALV10,"dddd") -> domingo | ALV10: =+ALS10+1 -> 46194
